Workbook
Name Lehrkraefte: Hilfslisten!$A$2:$A$20

Sheet Teilnehmer
A1: EH-Kurs – Teilnehmerliste 2026
B3: Datum: | E3: Beginn: | G3: Ende:
B4: Lehrkraft: | E4: Kursart:
B5: Registriernr.: | E5: QSEH-Kennziffer: | F5: 7.0103
B6: Lehrgangsort: | C6: Mercedes-Benz AG, PKW-Werk Rastatt
B7: Verantw. Arzt: | C7: Dr. Schmidt, Sabine | E7: Tel.: | F7: 07222/91-22111
B8: Masken-Charge:
A10: Nr | B10: Nachname | C10: Vorname | D10: Geburtsdatum | E10: Ersthelfer (x)
A11: 1
A12: 2
A13: 3
A14: 4
A15: 5
A16: 6
A17: 7
A18: 8
A19: 9
A20: 10
A21: 11
A22: 12
... A30: 20
B32: Gesamtanzahl: | C32: =COUNTA(B11:B30) | D32: davon Ersthelfer: | E32: =COUNTIF(E11:E30,"x")

Sheet Bescheinigungen
A2: =IF(Teilnehmer!B11<>"",Teilnehmer!B11,"") | C2: =IF(Teilnehmer!B11<>"",Teilnehmer!C11,"") | E2: geb. am: | F2: =IF(Teilnehmer!B11<>"",Teilnehmer!D11,"") | I2: =IF(Teilnehmer!B12<>"",Teilnehmer!B12,"") | K2: =IF(Teilnehmer!B12<>"",Teilnehmer!C12,"") | M2: geb. am: | N2: =IF(Teilnehmer!B12<>"",Teilnehmer!D12,"")
A3: Name | C3: Vorname | I3: Name | K3: Vorname
A5: hat an dem 9 Unterrichtseinheiten (Nettounterrichtszeit 9 x 45 Minuten) umfassenden Lehrgang | I5: hat an dem 9 Unterrichtseinheiten (Nettounterrichtszeit 9 x 45 Minuten) umfassenden Lehrgang
A7: am | B7: =Teilnehmer!C3 | C7: in der Zeit von | D7: =Teilnehmer!F3 | E7: Uhr bis | F7: =Teilnehmer!H3 | G7: Uhr | I7: am | J7: =Teilnehmer!C3 | K7: in der Zeit von | L7: =Teilnehmer!F3 | M7: Uhr bis | N7: =Teilnehmer!H3 | O7: Uhr
A9: unter der Leitung von | C9: =Teilnehmer!C4 | F9: erfolgreich teilgenommen. | I9: unter der Leitung von | K9: =Teilnehmer!C4 | N9: erfolgreich teilgenommen.
A11: Teilnehmerunterlagen ausgehändigt: | E11: X | F11: ja | G11: nein | I11: Teilnehmerunterlagen ausgehändigt: | M11: X | N11: ja | O11: nein
A14: Rastatt | B14: , den | C14: =Teilnehmer!C3 | I14: Rastatt | J14: , den | K14: =Teilnehmer!C3
A15: Ort | C15: Datum | E15: Unterschrift der Lehrkraft | I15: Ort | K15: Datum | M15: Unterschrift der Lehrkraft
E18: Ausbildungsverantwortlicher | M18: Ausbildungsverantwortlicher
A20: Name der ermächtigten Stelle: | D20: Mercedes-Benz AG, Werk Rastatt | I20: Name der ermächtigten Stelle: | L20: Mercedes-Benz AG, Werk Rastatt
A22: Kennziffer der ermächtigten Stelle | I22: Kennziffer der ermächtigten Stelle
A23: gemäß § 26 DGUV Vorschrift: | E23: 7.0103 | I23: gemäß § 26 DGUV Vorschrift: | M23: 7.0103
A25: Registriernummer der Schulung: | E25: =Teilnehmer!C5 | I25: Registriernummer der Schulung: | M25: =Teilnehmer!C5
A27: * Die Teilnahme an der Ausbildung in betrieblicher Erster Hilfe gilt als Schulung in Erster Hilfe gem. § 19 Fahrerlaubnis- | I27: * Die Teilnahme an der Ausbildung in betrieblicher Erster Hilfe gilt als Schulung in Erster Hilfe gem. § 19 Fahrerlaubnis-
A28: Verordnung (FeV). | I28: Verordnung (FeV).
A32: =IF(Teilnehmer!B13<>"",Teilnehmer!B13,"") | C32: =IF(Teilnehmer!B13<>"",Teilnehmer!C13,"") | E32: geb. am: | F32: =IF(Teilnehmer!B13<>"",Teilnehmer!D13,"") | I32: =IF(Teilnehmer!B14<>"",Teilnehmer!B14,"") | K32: =IF(Teilnehmer!B14<>"",Teilnehmer!C14,"") | M32: geb. am: | N32: =IF(Teilnehmer!B14<>"",Teilnehmer!D14,"")
A33: Name | C33: Vorname | I33: Name | K33: Vorname
A35: hat an dem 9 Unterrichtseinheiten (Nettounterrichtszeit 9 x 45 Minuten) umfassenden Lehrgang | I35: hat an dem 9 Unterrichtseinheiten (Nettounterrichtszeit 9 x 45 Minuten) umfassenden Lehrgang
A37: am | B37: =Teilnehmer!C3 | C37: in der Zeit von | D37: =Teilnehmer!F3 | E37: Uhr bis | F37: =Teilnehmer!H3 | G37: Uhr | I37: am | J37: =Teilnehmer!C3 | K37: in der Zeit von | L37: =Teilnehmer!F3 | M37: Uhr bis | N37: =Teilnehmer!H3 | O37: Uhr
A39: unter der Leitung von | C39: =Teilnehmer!C4 | F39: erfolgreich teilgenommen. | I39: unter der Leitung von | K39: =Teilnehmer!C4 | N39: erfolgreich teilgenommen.
A41: Teilnehmerunterlagen ausgehändigt: | E41: X | F41: ja | G41: nein | I41: Teilnehmerunterlagen ausgehändigt: | M41: X | N41: ja | O41: nein
A44: Rastatt | B44: , den | C44: =Teilnehmer!C3 | I44: Rastatt | J44: , den | K44: =Teilnehmer!C3
A45: Ort | C45: Datum | E45: Unterschrift der Lehrkraft | I45: Ort | K45: Datum | M45: Unterschrift der Lehrkraft
E48: Ausbildungsverantwortlicher | M48: Ausbildungsverantwortlicher
A50: Name der ermächtigten Stelle: | D50: Mercedes-Benz AG, Werk Rastatt | I50: Name der ermächtigten Stelle: | L50: Mercedes-Benz AG, Werk Rastatt
A52: Kennziffer der ermächtigten Stelle | I52: Kennziffer der ermächtigten Stelle
A53: gemäß § 26 DGUV Vorschrift: | E53: 7.0103 | I53: gemäß § 26 DGUV Vorschrift: | M53: 7.0103
A55: Registriernummer der Schulung: | E55: =Teilnehmer!C5 | I55: Registriernummer der Schulung: | M55: =Teilnehmer!C5
A57: * Die Teilnahme an der Ausbildung in betrieblicher Erster Hilfe gilt als Schulung in Erster Hilfe gem. § 19 Fahrerlaubnis- | I57: * Die Teilnahme an der Ausbildung in betrieblicher Erster Hilfe gilt als Schulung in Erster Hilfe gem. § 19 Fahrerlaubnis-
A58: Verordnung (FeV). | I58: Verordnung (FeV).
A62: =IF(Teilnehmer!B15<>"",Teilnehmer!B15,"") | C62: =IF(Teilnehmer!B15<>"",Teilnehmer!C15,"") | E62: geb. am: | F62: =IF(Teilnehmer!B15<>"",Teilnehmer!D15,"") | I62: =IF(Teilnehmer!B16<>"",Teilnehmer!B16,"") | K62: =IF(Teilnehmer!B16<>"",Teilnehmer!C16,"") | M62: geb. am: | N62: =IF(Teilnehmer!B16<>"",Teilnehmer!D16,"")
A63: Name | C63: Vorname | I63: Name | K63: Vorname
A65: hat an dem 9 Unterrichtseinheiten (Nettounterrichtszeit 9 x 45 Minuten) umfassenden Lehrgang | I65: hat an dem 9 Unterrichtseinheiten (Nettounterrichtszeit 9 x 45 Minuten) umfassenden Lehrgang
A67: am | B67: =Teilnehmer!C3 | C67: in der Zeit von | D67: =Teilnehmer!F3 | E67: Uhr bis | F67: =Teilnehmer!H3 | G67: Uhr | I67: am | J67: =Teilnehmer!C3 | K67: in der Zeit von | L67: =Teilnehmer!F3 | M67: Uhr bis | N67: =Teilnehmer!H3 | O67: Uhr
A69: unter der Leitung von | C69: =Teilnehmer!C4 | F69: erfolgreich teilgenommen. | I69: unter der Leitung von | K69: =Teilnehmer!C4 | N69: erfolgreich teilgenommen.
A71: Teilnehmerunterlagen ausgehändigt: | E71: X | F71: ja | G71: nein | I71: Teilnehmerunterlagen ausgehändigt: | M71: X | N71: ja | O71: nein
A74: Rastatt | B74: , den | C74: =Teilnehmer!C3 | I74: Rastatt | J74: , den | K74: =Teilnehmer!C3
A75: Ort | C75: Datum | E75: Unterschrift der Lehrkraft | I75: Ort | K75: Datum | M75: Unterschrift der Lehrkraft
E78: Ausbildungsverantwortlicher | M78: Ausbildungsverantwortlicher
A80: Name der ermächtigten Stelle: | D80: Mercedes-Benz AG, Werk Rastatt | I80: Name der ermächtigten Stelle: | L80: Mercedes-Benz AG, Werk Rastatt
...

Sheet BG-Liste
B5: Mercedes Benz AG | D5: BG-Metall Nord-Süd
B6: Mercedesstr. 1
B7: 76437 Rastatt
A10: 1 | B10: =IF(Teilnehmer!B11<>"",Teilnehmer!B11&", "&Teilnehmer!C11,"") | C10: =IF(Teilnehmer!D11<>"",Teilnehmer!D11,"")
A11: 2 | B11: =IF(Teilnehmer!B12<>"",Teilnehmer!B12&", "&Teilnehmer!C12,"") | C11: =IF(Teilnehmer!D12<>"",Teilnehmer!D12,"")
A12: 3 | B12: =IF(Teilnehmer!B13<>"",Teilnehmer!B13&", "&Teilnehmer!C13,"") | C12: =IF(Teilnehmer!D13<>"",Teilnehmer!D13,"")
A13: 4 | B13: =IF(Teilnehmer!B14<>"",Teilnehmer!B14&", "&Teilnehmer!C14,"") | C13: =IF(Teilnehmer!D14<>"",Teilnehmer!D14,"")
A14: 5 | B14: =IF(Teilnehmer!B15<>"",Teilnehmer!B15&", "&Teilnehmer!C15,"") | C14: =IF(Teilnehmer!D15<>"",Teilnehmer!D15,"")
A15: 6 | B15: =IF(Teilnehmer!B16<>"",Teilnehmer!B16&", "&Teilnehmer!C16,"") | C15: =IF(Teilnehmer!D16<>"",Teilnehmer!D16,"")
A16: 7 | B16: =IF(Teilnehmer!B17<>"",Teilnehmer!B17&", "&Teilnehmer!C17,"") | C16: =IF(Teilnehmer!D17<>"",Teilnehmer!D17,"")
A17: 8 | B17: =IF(Teilnehmer!B18<>"",Teilnehmer!B18&", "&Teilnehmer!C18,"") | C17: =IF(Teilnehmer!D18<>"",Teilnehmer!D18,"")
A18: 9 | B18: =IF(Teilnehmer!B19<>"",Teilnehmer!B19&", "&Teilnehmer!C19,"") | C18: =IF(Teilnehmer!D19<>"",Teilnehmer!D19,"")
A19: 10 | B19: =IF(Teilnehmer!B20<>"",Teilnehmer!B20&", "&Teilnehmer!C20,"") | C19: =IF(Teilnehmer!D20<>"",Teilnehmer!D20,"")
B22: Dr. Schmidt, Sabine
B23: 07222/91-22111
B24: sabine.m.schmidt@mercedes-benz.com
D25: =Teilnehmer!C3
C29: =Teilnehmer!C3
B31: 7.0103 | C31: =Teilnehmer!C4
B33: =" "&Teilnehmer!C5 | C33: Mercedes Benz AG, PKW Werk
C36: Mercedes Benz AG
C37: Werksärztlicher Dienst
C38: PKW-Werk Rastatt
C39: Mercedesstrasse 1
B40: =Teilnehmer!C3 | C40: 76437 Rastatt
B48: Mercedes Benz AG | D48: BG-Metall Nord-Süd
B49: Mercedesstr. 1
B50: 76437 Rastatt
A53: 1 | B53: =IF(Teilnehmer!B21<>"",Teilnehmer!B21&", "&Teilnehmer!C21,"") | C53: =IF(Teilnehmer!D21<>"",Teilnehmer!D21,"")
A54: 2 | B54: =IF(Teilnehmer!B22<>"",Teilnehmer!B22&", "&Teilnehmer!C22,"") | C54: =IF(Teilnehmer!D22<>"",Teilnehmer!D22,"")
A55: 3 | B55: =IF(Teilnehmer!B23<>"",Teilnehmer!B23&", "&Teilnehmer!C23,"") | C55: =IF(Teilnehmer!D23<>"",Teilnehmer!D23,"")
A56: 4 | B56: =IF(Teilnehmer!B24<>"",Teilnehmer!B24&", "&Teilnehmer!C24,"") | C56: =IF(Teilnehmer!D24<>"",Teilnehmer!D24,"")
A57: 5 | B57: =IF(Teilnehmer!B25<>"",Teilnehmer!B25&", "&Teilnehmer!C25,"") | C57: =IF(Teilnehmer!D25<>"",Teilnehmer!D25,"")
A58: 6 | B58: =IF(Teilnehmer!B26<>"",Teilnehmer!B26&", "&Teilnehmer!C26,"") | C58: =IF(Teilnehmer!D26<>"",Teilnehmer!D26,"")
A59: 7 | B59: =IF(Teilnehmer!B27<>"",Teilnehmer!B27&", "&Teilnehmer!C27,"") | C59: =IF(Teilnehmer!D27<>"",Teilnehmer!D27,"")
A60: 8 | B60: =IF(Teilnehmer!B28<>"",Teilnehmer!B28&", "&Teilnehmer!C28,"") | C60: =IF(Teilnehmer!D28<>"",Teilnehmer!D28,"")
A61: 9 | B61: =IF(Teilnehmer!B29<>"",Teilnehmer!B29&", "&Teilnehmer!C29,"") | C61: =IF(Teilnehmer!D29<>"",Teilnehmer!D29,"")
A62: 10 | B62: =IF(Teilnehmer!B30<>"",Teilnehmer!B30&", "&Teilnehmer!C30,"") | C62: =IF(Teilnehmer!D30<>"",Teilnehmer!D30,"")
B65: Dr. Schmidt, Sabine
B66: 07222/91-22111
...

Sheet Lehrgangsdoku
A1: Lehrgangsdokumentation
A2: gem. Abschnitt 2.4.6 DGUV Grundsatz 304-001
B4: Angaben zur Ausbildungsstelle
B5: Bezeichnung
B6: Mercedes-Benz AG | E6: QSEH-Kennziffer: | F6: =Teilnehmer!F5
B8: Straße / Hausnr.
B9: Mercedesstr. 1
B11: PLZ / Ort
B12: 76437 Rastatt
B14: Angaben zum Seminar
B15: =IF(Teilnehmer!F4="EH-Ausbildung","X"," ")&" EH-Ausbildung "&IF(Teilnehmer!F4="EH-Fortbildung","X"," ")&" EH-Fortbildung "&IF(Teilnehmer!F4="EH-Schulung","X"," ")&" EH-Schulung"
B17: Registriernummer: | C17: =Teilnehmer!C5 | E17: Lehrgangsort: | F17: Mercedes-Benz AG, PKW-Werk Rastatt
B18: (aus dem QSEH-Portal) | F18: Gebäude 39, Gesundheitszentrum 1.OG
B20: Lehrgangsdatum: | C20: =Teilnehmer!C3 | E20: Uhrzeit: | F20: ="von "&TEXT(Teilnehmer!F3,"HH:MM")&" Uhr bis "&TEXT(Teilnehmer!H3,"HH:MM")&" Uhr"
B22: Name der Lehrkraft: | C22: =Teilnehmer!C4
B24: Verantwortlicher Arzt: | C24: =Teilnehmer!C7
B26: Masken-Charge: | C26: =Teilnehmer!C8
B28: Anzahl der Teilnehmenden
B30: Gesamtanzahl der Teilnehmenden: | E30: =Teilnehmer!C32
B31: (entspricht der Anzahl der Teilnehmerdatenblätter)
B33: davon betriebliche Ersthelfende: | E33: =Teilnehmer!E32
B35: Anlagen
B36: Alle Teilnehmenden sind mit Namen, Vornamen, Geburtsdatum und Unterschrift zu erfassen. Für UVT-Teilnehmende sind zusätzlich der Name und die Anschrift des Arbeitgebers sowie der kostentragende UVT zu ergänzen. Dies kann durch einzelne Teilnehmerdatenblätter erfolgen.
B40: Die Dokumentation ist fünf Jahre aufzubewahren und auf Anforderung dem Unfallversicherungsträger vorzulegen.
B42: Für die Richtigkeit der Angaben:
B47: ="Rastatt, "&TEXT(Teilnehmer!C3,"DD.MM.YYYY") | E47: ="Rastatt, "&TEXT(Teilnehmer!C3,"DD.MM.YYYY")
B48: Ort, Datum Unterschrift Lehrgangsleitung | E48: Ort, Datum Unterschrift Ausbildungsstelle
B50: Stand: 2026

Sheet Hilfslisten
A1: Lehrkräfte
A2: Putschler, Walter
A3: Kaya, Michelle
A4: Krempl, Elke
A5: Breig, Bernd
A6: Zuber, Harry
A7: Jochim, Benjamin
A8: Siebert, Emanuel
