Workbook
Name NamenListe: Hilfslisten!$F$23:$F$38
Name REKOListe: Hilfslisten!$H$23:$H$42
Name KatListe: Hilfslisten!$J$23:$J$26

Sheet Dashboard
B1: LARIS Dashboard - Gesamtübersicht
B4: Gesamt Meldungen: | D4: =C16 | E4: Erledigt: | G4: =D16 | H4: Offen: | J4: =E16
B6: Bereich | C6: Meldungen | D6: Erledigt | E6: Offen | G6: Kat A | H6: Kat B | I6: Kat C | J6: Kat D | L6: Leiter
B7: Sekretariat | C7: =COUNTA('Sekretariat'!B5:B504) | D7: =COUNTA('Sekretariat'!H5:H504) | E7: =C7-D7 | G7: =COUNTIF('Sekretariat'!J5:J504,"A") | H7: =COUNTIF('Sekretariat'!J5:J504,"B") | I7: =COUNTIF('Sekretariat'!J5:J504,"C") | J7: =COUNTIF('Sekretariat'!J5:J504,"D") | L7: Emily Schmidt
B8: EDV | C8: =COUNTA('EDV'!B5:B504) | D8: =COUNTA('EDV'!H5:H504) | E8: =C8-D8 | G8: =COUNTIF('EDV'!J5:J504,"A") | H8: =COUNTIF('EDV'!J5:J504,"B") | I8: =COUNTIF('EDV'!J5:J504,"C") | J8: =COUNTIF('EDV'!J5:J504,"D") | L8: Siebert
B9: Med.&Verbr.-stoff | C9: =COUNTA('Med.&Verbr.-stoff'!B5:B504) | D9: =COUNTA('Med.&Verbr.-stoff'!H5:H504) | E9: =C9-D9 | G9: =COUNTIF('Med.&Verbr.-stoff'!J5:J504,"A") | H9: =COUNTIF('Med.&Verbr.-stoff'!J5:J504,"B") | I9: =COUNTIF('Med.&Verbr.-stoff'!J5:J504,"C") | J9: =COUNTIF('Med.&Verbr.-stoff'!J5:J504,"D") | L9: Zeller
B10: WD-Fzg & Schutzkleidg | C10: =COUNTA('WD-Fzg & Schutzkleidg'!B5:B504) | D10: =COUNTA('WD-Fzg & Schutzkleidg'!H5:H504) | E10: =C10-D10 | G10: =COUNTIF('WD-Fzg & Schutzkleidg'!J5:J504,"A") | H10: =COUNTIF('WD-Fzg & Schutzkleidg'!J5:J504,"B") | I10: =COUNTIF('WD-Fzg & Schutzkleidg'!J5:J504,"C") | J10: =COUNTIF('WD-Fzg & Schutzkleidg'!J5:J504,"D") | L10: Wunsch
B11: RTW & MPG | C11: =COUNTA('RTW & MPG'!B5:B504) | D11: =COUNTA('RTW & MPG'!H5:H504) | E11: =C11-D11 | G11: =COUNTIF('RTW & MPG'!J5:J504,"A") | H11: =COUNTIF('RTW & MPG'!J5:J504,"B") | I11: =COUNTIF('RTW & MPG'!J5:J504,"C") | J11: =COUNTIF('RTW & MPG'!J5:J504,"D") | L11: Göpfrich
B12: Organisation Ambulanz | C12: =COUNTA('Organisation Ambulanz'!B5:B504) | D12: =COUNTA('Organisation Ambulanz'!H5:H504) | E12: =C12-D12 | G12: =COUNTIF('Organisation Ambulanz'!J5:J504,"A") | H12: =COUNTIF('Organisation Ambulanz'!J5:J504,"B") | I12: =COUNTIF('Organisation Ambulanz'!J5:J504,"C") | J12: =COUNTIF('Organisation Ambulanz'!J5:J504,"D") | L12: Wunsch
B13: Ablauf&Prozessprobleme | C13: =COUNTA('Ablauf&Prozessprobleme'!B5:B504) | D13: =COUNTA('Ablauf&Prozessprobleme'!H5:H504) | E13: =C13-D13 | G13: =COUNTIF('Ablauf&Prozessprobleme'!J5:J504,"A") | H13: =COUNTIF('Ablauf&Prozessprobleme'!J5:J504,"B") | I13: =COUNTIF('Ablauf&Prozessprobleme'!J5:J504,"C") | J13: =COUNTIF('Ablauf&Prozessprobleme'!J5:J504,"D") | L13: Putschler
B14: BGF | C14: =COUNTA('BGF'!B5:B504) | D14: =COUNTA('BGF'!H5:H504) | E14: =C14-D14 | G14: =COUNTIF('BGF'!J5:J504,"A") | H14: =COUNTIF('BGF'!J5:J504,"B") | I14: =COUNTIF('BGF'!J5:J504,"C") | J14: =COUNTIF('BGF'!J5:J504,"D") | L14: Zieger-Buchta
B15: Hygiene | C15: =COUNTA('Hygiene'!B5:B504) | D15: =COUNTA('Hygiene'!H5:H504) | E15: =C15-D15 | G15: =COUNTIF('Hygiene'!J5:J504,"A") | H15: =COUNTIF('Hygiene'!J5:J504,"B") | I15: =COUNTIF('Hygiene'!J5:J504,"C") | J15: =COUNTIF('Hygiene'!J5:J504,"D") | L15: Wunsch
B16: GESAMT | C16: =SUM(C7:C15) | D16: =SUM(D7:D15) | E16: =SUM(E7:E15) | G16: =SUM(G7:G15) | H16: =SUM(H7:H15) | I16: =SUM(I7:I15) | J16: =SUM(J7:J15)
B18: Legende Farbmarkierungen in den Bereichs-Sheets:
C19: Nr.-Spalte blau | D19: Neue Meldung (letzte 7 Tage)
C20: Zeile gelb | D20: Meldung offen (noch nicht erledigt)
C21: Zeile grün | D21: Meldung erledigt
C22: Zeile rot | D22: Überfällig (>14 Tage ohne Kenntnisnahme)
C23: Kategorie A | D23: Unsichere Handlung
C24: Kategorie B | D24: Beinahefehler ohne Folgen
C25: Kategorie C | D25: Fehler mit leichten bis mittelschweren Folgen
C26: Kategorie D | D26: Fehler mit gravierenden Folgen

Sheet Info
B1: LARIS - Lernende Abweichungs-, Risiko- und Informationssammlung
B3: Werksärztlicher Dienst Mercedes-Benz Rastatt/Kuppenheim
B4: Version 2026 - Ohne Makros & Blattschutz
B6: Die Liste dient zur Meldung von:
B7: ● | C7: Vorkommnissen
B8: ● | C8: fehlendem oder fehlerhaftem Material
B9: ● | C9: Administrationsbedarf im Bereich
C10: an den jeweiligen Bereichsleiter!
B12: Informationen die alle betreffen müssen über E-Mail kommuniziert werden!
B14: Erstellen einer Meldung
B15: ● | C15: Unten den entsprechenden Reiter für den Bereich auswählen
B16: ● | C16: Im Feld "Meldung durch" den eigenen Namen auswählen (Dropdown)
B17: ● | C17: Datum im Feld "Meldung am" eintragen (Format: TT.MM.JJJJ)
B18: ● | C18: Info bei "Thema" eintragen
B19: ● | C19: Auf den grünen "Mail an Bereichsleiter"-Link klicken (öffnet Outlook automatisch)
B20: ● | C20: Speichern
B22: Abarbeiten einer Meldung durch den Bereichsleiter
B23: ● | C23: Bei Kenntnisnahme im Feld "Kenntnisnahme durch" eigenen Namen auswählen und Datum eintragen
B24: ● | C24: Massnahmen im entsprechenden Feld dokumentieren
B25: ● | C25: Nach Erledigung im Feld "Erledigt durch" eigenen Namen auswählen und Datum eintragen
B26: ● | C26: Evtl. weitere Infos im entsprechenden Feld eintragen
B27: ● | C27: In Spalte "In REKO..." auswählen wie besprochen wurde
B29: Hinweise zur neuen Version
B30: ✓ | C30: Kein Blattschutz - alle Zellen sind frei editierbar
B31: ✓ | C31: Keine Makros/ActiveX - kein Hängen, keine Sicherheitswarnungen
B32: ✓ | C32: Dropdown-Listen für Namen und Kategorien (Klick auf die Zelle)
B33: ✓ | C33: Datumsfelder manuell ausfüllen (Format: TT.MM.JJJJ HH:MM)
B34: ✓ | C34: Meldungs- und Erledigungszähler werden automatisch berechnet (Formeln)
B35: ✓ | C35: Mail-Versand per klickbarem Link (öffnet Outlook mit Empfänger + Betreff + BCC)
B36: ✓ | C36: Dashboard-Reiter zeigt Gesamtübersicht aller Bereiche auf einen Blick
B37: ✓ | C37: Farbige Zeilen: Grün=Erledigt, Gelb=Offen, Rot=Überfällig (>14 Tage)
B38: ✓ | C38: Neue Meldungen (letzte 7 Tage) werden in der Nr.-Spalte blau markiert
B39: ✓ | C39: Druckoptimiert: Querformat A4, Kopfzeile wiederholt sich automatisch
B41: Bereich | D41: Leiter | F41: Stellvertreter
B42: Sekretariat | D42: Emily Schmidt | F42: Larissa Radimersky
B43: EDV | D43: Siebert
B44: Med.&Verbr.-stoff | D44: Zeller | F44: Breig
B45: WD-Fzg & Schutzkleidg | D45: Wunsch
B46: RTW & MPG | D46: Göpfrich
B47: Organisation Ambulanz | D47: Wunsch
...

Sheet Sekretariat
A1: Sekretariat
A2: Meldungen: | B2: =COUNTA(B5:B504) | C2: Erledigt: | D2: =COUNTA(H5:H504) | E2: Offen: | F2: =B2-D2 | H2: A = unsichere Handlung B = Beinahefehler ohne Folgen C = Fehler mit leichten bis mittelschweren Folgen D = Fehler mit gravierenden Folgen
A3: ✉ Mail an Bereichsleiter: Emily Schmidt (emily_kim.schmidt@mercedes-benz.com) | H3: BCC an: Putschler (walter.putschler@mercedes-benz.com)
A4: Nr. | B4: Meldung am | C4: Meldung durch | D4: Thema | E4: Kenntnisnahme am | F4: Kenntnisnahme durch | G4: Massnahme | H4: Erledigt am | I4: Erledigt durch | J4: Kategorie | K4: Info | L4: In REKO oder Persönlich besprochen?
A5: =IF(B5<>"",ROW()-4,"")
A6: =IF(B6<>"",ROW()-4,"")
A7: =IF(B7<>"",ROW()-4,"")
A8: =IF(B8<>"",ROW()-4,"")
A9: =IF(B9<>"",ROW()-4,"")
A10: =IF(B10<>"",ROW()-4,"")
A11: =IF(B11<>"",ROW()-4,"")
A12: =IF(B12<>"",ROW()-4,"")
A13: =IF(B13<>"",ROW()-4,"")
A14: =IF(B14<>"",ROW()-4,"")
A15: =IF(B15<>"",ROW()-4,"")
A16: =IF(B16<>"",ROW()-4,"")
... A54: =IF(B54<>"",ROW()-4,"")

Sheet EDV
A1: EDV
A2: Meldungen: | B2: =COUNTA(B5:B504) | C2: Erledigt: | D2: =COUNTA(H5:H504) | E2: Offen: | F2: =B2-D2 | H2: A = unsichere Handlung B = Beinahefehler ohne Folgen C = Fehler mit leichten bis mittelschweren Folgen D = Fehler mit gravierenden Folgen
A3: ✉ Mail an Bereichsleiter: Siebert (emanuel.siebert@mercedes-benz.com) | H3: BCC an: Putschler (walter.putschler@mercedes-benz.com)
A4: Nr. | B4: Meldung am | C4: Meldung durch | D4: Thema | E4: Kenntnisnahme am | F4: Kenntnisnahme durch | G4: Massnahme | H4: Erledigt am | I4: Erledigt durch | J4: Kategorie | K4: Info | L4: In REKO oder Persönlich besprochen?
A5: =IF(B5<>"",ROW()-4,"")
A6: =IF(B6<>"",ROW()-4,"")
A7: =IF(B7<>"",ROW()-4,"")
A8: =IF(B8<>"",ROW()-4,"")
A9: =IF(B9<>"",ROW()-4,"")
A10: =IF(B10<>"",ROW()-4,"")
A11: =IF(B11<>"",ROW()-4,"")
A12: =IF(B12<>"",ROW()-4,"")
A13: =IF(B13<>"",ROW()-4,"")
A14: =IF(B14<>"",ROW()-4,"")
A15: =IF(B15<>"",ROW()-4,"")
A16: =IF(B16<>"",ROW()-4,"")
... A54: =IF(B54<>"",ROW()-4,"")

Sheet Med.&Verbr.-stoff
A1: Med.&Verbr.-stoff
A2: Meldungen: | B2: =COUNTA(B5:B504) | C2: Erledigt: | D2: =COUNTA(H5:H504) | E2: Offen: | F2: =B2-D2 | H2: A = unsichere Handlung B = Beinahefehler ohne Folgen C = Fehler mit leichten bis mittelschweren Folgen D = Fehler mit gravierenden Folgen
A3: ✉ Mail an Bereichsleiter: Zeller (tobias_felix.zeller@mercedes-benz.com) | H3: BCC an: Putschler (walter.putschler@mercedes-benz.com)
A4: Nr. | B4: Meldung am | C4: Meldung durch | D4: Thema | E4: Kenntnisnahme am | F4: Kenntnisnahme durch | G4: Massnahme | H4: Erledigt am | I4: Erledigt durch | J4: Kategorie | K4: Info | L4: In REKO oder Persönlich besprochen?
A5: =IF(B5<>"",ROW()-4,"")
A6: =IF(B6<>"",ROW()-4,"")
A7: =IF(B7<>"",ROW()-4,"")
A8: =IF(B8<>"",ROW()-4,"")
A9: =IF(B9<>"",ROW()-4,"")
A10: =IF(B10<>"",ROW()-4,"")
A11: =IF(B11<>"",ROW()-4,"")
A12: =IF(B12<>"",ROW()-4,"")
A13: =IF(B13<>"",ROW()-4,"")
A14: =IF(B14<>"",ROW()-4,"")
A15: =IF(B15<>"",ROW()-4,"")
A16: =IF(B16<>"",ROW()-4,"")
... A54: =IF(B54<>"",ROW()-4,"")

Sheet WD-Fzg & Schutzkleidg
A1: WD-Fzg & Schutzkleidg
A2: Meldungen: | B2: =COUNTA(B5:B504) | C2: Erledigt: | D2: =COUNTA(H5:H504) | E2: Offen: | F2: =B2-D2 | H2: A = unsichere Handlung B = Beinahefehler ohne Folgen C = Fehler mit leichten bis mittelschweren Folgen D = Fehler mit gravierenden Folgen
A3: ✉ Mail an Bereichsleiter: Wunsch (Fabian.Wunsch@mercedes-benz.com) | H3: BCC an: Putschler (walter.putschler@mercedes-benz.com)
A4: Nr. | B4: Meldung am | C4: Meldung durch | D4: Thema | E4: Kenntnisnahme am | F4: Kenntnisnahme durch | G4: Massnahme | H4: Erledigt am | I4: Erledigt durch | J4: Kategorie | K4: Info | L4: In REKO oder Persönlich besprochen?
A5: =IF(B5<>"",ROW()-4,"")
A6: =IF(B6<>"",ROW()-4,"")
A7: =IF(B7<>"",ROW()-4,"")
A8: =IF(B8<>"",ROW()-4,"")
A9: =IF(B9<>"",ROW()-4,"")
A10: =IF(B10<>"",ROW()-4,"")
A11: =IF(B11<>"",ROW()-4,"")
A12: =IF(B12<>"",ROW()-4,"")
A13: =IF(B13<>"",ROW()-4,"")
A14: =IF(B14<>"",ROW()-4,"")
A15: =IF(B15<>"",ROW()-4,"")
A16: =IF(B16<>"",ROW()-4,"")
... A54: =IF(B54<>"",ROW()-4,"")

Sheet RTW & MPG
A1: RTW & MPG
A2: Meldungen: | B2: =COUNTA(B5:B504) | C2: Erledigt: | D2: =COUNTA(H5:H504) | E2: Offen: | F2: =B2-D2 | H2: A = unsichere Handlung B = Beinahefehler ohne Folgen C = Fehler mit leichten bis mittelschweren Folgen D = Fehler mit gravierenden Folgen
A3: ✉ Mail an Bereichsleiter: Göpfrich (Markus.Goepfrich@mercedes-benz.com) | H3: BCC an: Putschler (walter.putschler@mercedes-benz.com)
A4: Nr. | B4: Meldung am | C4: Meldung durch | D4: Thema | E4: Kenntnisnahme am | F4: Kenntnisnahme durch | G4: Massnahme | H4: Erledigt am | I4: Erledigt durch | J4: Kategorie | K4: Info | L4: In REKO oder Persönlich besprochen?
A5: =IF(B5<>"",ROW()-4,"")
A6: =IF(B6<>"",ROW()-4,"")
A7: =IF(B7<>"",ROW()-4,"")
A8: =IF(B8<>"",ROW()-4,"")
A9: =IF(B9<>"",ROW()-4,"")
A10: =IF(B10<>"",ROW()-4,"")
A11: =IF(B11<>"",ROW()-4,"")
A12: =IF(B12<>"",ROW()-4,"")
A13: =IF(B13<>"",ROW()-4,"")
A14: =IF(B14<>"",ROW()-4,"")
A15: =IF(B15<>"",ROW()-4,"")
A16: =IF(B16<>"",ROW()-4,"")
... A54: =IF(B54<>"",ROW()-4,"")

Sheet Organisation Ambulanz
A1: Organisation Ambulanz
A2: Meldungen: | B2: =COUNTA(B5:B504) | C2: Erledigt: | D2: =COUNTA(H5:H504) | E2: Offen: | F2: =B2-D2 | H2: A = unsichere Handlung B = Beinahefehler ohne Folgen C = Fehler mit leichten bis mittelschweren Folgen D = Fehler mit gravierenden Folgen
A3: ✉ Mail an Bereichsleiter: Wunsch (Fabian.Wunsch@mercedes-benz.com) | H3: BCC an: Putschler (walter.putschler@mercedes-benz.com)
A4: Nr. | B4: Meldung am | C4: Meldung durch | D4: Thema | E4: Kenntnisnahme am | F4: Kenntnisnahme durch | G4: Massnahme | H4: Erledigt am | I4: Erledigt durch | J4: Kategorie | K4: Info | L4: In REKO oder Persönlich besprochen?
A5: =IF(B5<>"",ROW()-4,"")
A6: =IF(B6<>"",ROW()-4,"")
A7: =IF(B7<>"",ROW()-4,"")
A8: =IF(B8<>"",ROW()-4,"")
A9: =IF(B9<>"",ROW()-4,"")
A10: =IF(B10<>"",ROW()-4,"")
A11: =IF(B11<>"",ROW()-4,"")
A12: =IF(B12<>"",ROW()-4,"")
A13: =IF(B13<>"",ROW()-4,"")
A14: =IF(B14<>"",ROW()-4,"")
A15: =IF(B15<>"",ROW()-4,"")
A16: =IF(B16<>"",ROW()-4,"")
... A54: =IF(B54<>"",ROW()-4,"")

Sheet Ablauf&Prozessprobleme
A1: Ablauf&Prozessprobleme
A2: Meldungen: | B2: =COUNTA(B5:B504) | C2: Erledigt: | D2: =COUNTA(H5:H504) | E2: Offen: | F2: =B2-D2 | H2: A = unsichere Handlung B = Beinahefehler ohne Folgen C = Fehler mit leichten bis mittelschweren Folgen D = Fehler mit gravierenden Folgen
A3: ✉ Mail an Bereichsleiter: Putschler (walter.putschler@mercedes-benz.com) | H3: BCC an: Putschler (walter.putschler@mercedes-benz.com)
A4: Nr. | B4: Meldung am | C4: Meldung durch | D4: Thema | E4: Kenntnisnahme am | F4: Kenntnisnahme durch | G4: Massnahme | H4: Erledigt am | I4: Erledigt durch | J4: Kategorie | K4: Info | L4: In REKO oder Persönlich besprochen?
A5: =IF(B5<>"",ROW()-4,"")
A6: =IF(B6<>"",ROW()-4,"")
A7: =IF(B7<>"",ROW()-4,"")
A8: =IF(B8<>"",ROW()-4,"")
A9: =IF(B9<>"",ROW()-4,"")
A10: =IF(B10<>"",ROW()-4,"")
A11: =IF(B11<>"",ROW()-4,"")
A12: =IF(B12<>"",ROW()-4,"")
A13: =IF(B13<>"",ROW()-4,"")
A14: =IF(B14<>"",ROW()-4,"")
A15: =IF(B15<>"",ROW()-4,"")
A16: =IF(B16<>"",ROW()-4,"")
... A54: =IF(B54<>"",ROW()-4,"")

Sheet BGF
A1: BGF
A2: Meldungen: | B2: =COUNTA(B5:B504) | C2: Erledigt: | D2: =COUNTA(H5:H504) | E2: Offen: | F2: =B2-D2 | H2: A = unsichere Handlung B = Beinahefehler ohne Folgen C = Fehler mit leichten bis mittelschweren Folgen D = Fehler mit gravierenden Folgen
A3: ✉ Mail an Bereichsleiter: Zieger-Buchta (katrin.zieger-buchta@mercedes-benz.com) | H3: BCC an: Putschler (walter.putschler@mercedes-benz.com)
A4: Nr. | B4: Meldung am | C4: Meldung durch | D4: Thema | E4: Kenntnisnahme am | F4: Kenntnisnahme durch | G4: Massnahme | H4: Erledigt am | I4: Erledigt durch | J4: Kategorie | K4: Info | L4: In REKO oder Persönlich besprochen?
A5: =IF(B5<>"",ROW()-4,"")
A6: =IF(B6<>"",ROW()-4,"")
A7: =IF(B7<>"",ROW()-4,"")
A8: =IF(B8<>"",ROW()-4,"")
A9: =IF(B9<>"",ROW()-4,"")
A10: =IF(B10<>"",ROW()-4,"")
A11: =IF(B11<>"",ROW()-4,"")
A12: =IF(B12<>"",ROW()-4,"")
A13: =IF(B13<>"",ROW()-4,"")
A14: =IF(B14<>"",ROW()-4,"")
A15: =IF(B15<>"",ROW()-4,"")
A16: =IF(B16<>"",ROW()-4,"")
... A54: =IF(B54<>"",ROW()-4,"")

Sheet Hygiene
A1: Hygiene
A2: Meldungen: | B2: =COUNTA(B5:B504) | C2: Erledigt: | D2: =COUNTA(H5:H504) | E2: Offen: | F2: =B2-D2 | H2: A = unsichere Handlung B = Beinahefehler ohne Folgen C = Fehler mit leichten bis mittelschweren Folgen D = Fehler mit gravierenden Folgen
A3: ✉ Mail an Bereichsleiter: Wunsch (Fabian.Wunsch@mercedes-benz.com) | H3: BCC an: Putschler (walter.putschler@mercedes-benz.com)
A4: Nr. | B4: Meldung am | C4: Meldung durch | D4: Thema | E4: Kenntnisnahme am | F4: Kenntnisnahme durch | G4: Massnahme | H4: Erledigt am | I4: Erledigt durch | J4: Kategorie | K4: Info | L4: In REKO oder Persönlich besprochen?
A5: =IF(B5<>"",ROW()-4,"")
A6: =IF(B6<>"",ROW()-4,"")
A7: =IF(B7<>"",ROW()-4,"")
A8: =IF(B8<>"",ROW()-4,"")
A9: =IF(B9<>"",ROW()-4,"")
A10: =IF(B10<>"",ROW()-4,"")
A11: =IF(B11<>"",ROW()-4,"")
A12: =IF(B12<>"",ROW()-4,"")
A13: =IF(B13<>"",ROW()-4,"")
A14: =IF(B14<>"",ROW()-4,"")
A15: =IF(B15<>"",ROW()-4,"")
A16: =IF(B16<>"",ROW()-4,"")
... A54: =IF(B54<>"",ROW()-4,"")

Sheet Fehlerkategorien
A1: Kategorie | B1: Beschreibung | C1: Details | D1: Beispiele
A2: D | B2: Fehler mit gravierenden Folgen | C2: daraus resultierende schwere Gesundheitsschäden, wesentliche finanzielle Nachteile oder ein erheblicher Imageverlust | D2: gesetzl. vorgeschriebene Unterweisungen oder Überprüfungen liegen nicht vor, Behandlungsfehler mit Konsequenzen, Defekte von Notfallgeräten
A3: C | B3: Fehler mit leichten bis mittelschweren Folgen | C3: Fehler mit Gesundheitsschäden, Einsatzfähigkeit HSM gefährdet, Fehler führte zu externer Kundenbeschwerde, Vorgegebener Standard wird nicht durchgeführt | D3: Behandlungsfehler ohne Konsequenzen, Termin- oder Materialkonflikt nicht rechtzeitig erkannt, Ausgang von Medikamenten, NADOK Protokolle nicht vollständig ausgefüllt
A4: B | B4: Beinahefehler ohne Folgen | C4: ein Fehler wurde noch vor seinem wirksamen Eintreten erkannt, bzw. durch Gegenmaßnahmen können Folgen noch abgefangen werden | D4: Termin- oder Materialkonflikt gerade noch rechtzeitig erkannt und behoben
A5: A | B5: unsichere Handlung | C5: es wird unsauber gearbeitet, aber es entsteht kein Schaden | D5: Vorgaben werden nicht eingehalten, z.B. Eintrag der RTW Checks in FB 260

Sheet Hilfslisten
A1: Mitarbeiterliste & E-Mail-Adressen
A2: Name | B2: E-Mail | C2: Funktion/Bereich | D2: Notiz
A3: Dr. Markus Frei | B3: markus.frei@mercedes-benz.com | C3: Arzt
A4: Dr. Sabine Schmidt | B4: sabine.m.schmidt@mercedes-benz.com | C4: Ärztin
A5: Dr. Lilla Vitez | B5: lilla.vitez@mercedes-benz.com | C5: Ärztin
A6: Bernd Breig | B6: bernd.breig@mercedes-benz.com | C6: Stv. Med.&Verbr.-stoff
A7: Elke Krempl | B7: elke.krempl@mercedes-benz.com | C7: Mitarbeiterin
A8: Emanuel Siebert | B8: emanuel.siebert@mercedes-benz.com | C8: Leiter EDV
A9: Walter Putschler | B9: walter.putschler@mercedes-benz.com | C9: Leiter Ablauf&Prozessprobleme | D9: BCC-Empfänger
A10: Benjamin Jochim | B10: benjamin.jochim@mercedes-benz.com | C10: Mitarbeiter
A11: Harry Zuber | B11: harry.zuber@mercedes-benz.com | C11: Mitarbeiter
A12: Markus Göpfrich | B12: Markus.Goepfrich@mercedes-benz.com | C12: Leiter RTW & MPG | D12: Name im Dropdown: Göpfrich
A13: Tobias Zeller | B13: tobias_felix.zeller@mercedes-benz.com | C13: Leiter Med.&Verbr.-stoff
A14: Emily Kim Schmidt | B14: emily_kim.schmidt@mercedes-benz.com | C14: Leiterin Sekretariat
A15: Katrin Zieger-Buchta | B15: katrin.zieger-buchta@mercedes-benz.com | C15: Leiterin BGF
A16: Susanne Müller-Horn | B16: Susanne.Mueller-Horn@mercedes-benz.com | C16: Stv. BGF
A17: Larissa Radimersky | B17: larissa.radimersky@mercedes-benz.com | C17: Stv. Sekretariat
A18: Fabian Wunsch | B18: Fabian.Wunsch@mercedes-benz.com | C18: Leiter WD-Fzg, Org. Ambulanz, Hygiene
F22: Dropdown: Namen | H22: Dropdown: REKO | J22: Dropdown: Kategorie
F23: Breig | H23: REKO | J23: A
F24: Dr. Vitez | H24: Nicht erforderlich | J24: B
F25: Dr.Frei | H25: Besprochen mit Dr.Frei | J25: C
F26: Dr.Schmidt | H26: Besprochen mit Dr.Schmidt | J26: D
F27: Göpfrich | H27: Besprochen mit Dr. Vitez
F28: Jochim | H28: Besprochen mit Breig
F29: Krempl | H29: Besprochen mit Krempl
F30: Müller-Horn | H30: Besprochen mit Siebert
F31: Putschler | H31: Besprochen mit Putschler
F32: Radimersky | H32: Besprochen mit Jochim
F33: Schmidt | H33: Besprochen mit Zuber
F34: Siebert | H34: Besprochen mit Göpfrich
F35: Wunsch | H35: Besprochen mit Jochim
F36: Zeller | H36: Besprochen mit Wunsch
F37: Zieger-Buchta | H37: Besprochen mit Zeller
F38: Zuber | H38: Besprochen mit Schmidt
H39: Besprochen mit Zieger-Buchta
H40: Besprochen mit Müller-Horn
H41: Besprochen mit Radimersky
H42: Besprochen mit Wunsch
